<?xml version="1.0" ?>
<!-- =================================================================================== -->
<!-- |    This document was autogenerated by xacro from src/yamax_description/robots/yamax.xacro | -->
<!-- |    EDITING THIS FILE BY HAND IS NOT RECOMMENDED                                 | -->
<!-- =================================================================================== -->
<robot name="yamax" xmlns:xacro="http://ros.org/wiki/xacro">
  <material name="Grey">
    <color rgba="0.5820 0.6445 0.6484 1.0"/>
  </material>
  <material name="Orange">
    <color rgba="0.8984 0.4922 0.1328 1.0"/>
  </material>
  <material name="Black">
    <color rgba="0.1718 0.2421 0.3125 1.0"/>
  </material>
  <link name="head">
    <visual>
      <origin rpy="0 0 0" xyz="0 0 0"/>
      <geometry>
        <box size="0.035 0.035 0.023"/>
      </geometry>
      <material name="Grey"/>
    </visual>
    <collision>
      <origin rpy="0 0 0" xyz="0 0 0"/>
      <geometry>
        <box size="0.035 0.035 0.023"/>
      </geometry>
    </collision>
    <inertial>
      <origin xyz="0 0 0"/>
      <mass value="0.012"/>
      <inertia ixx="1.754e-06" ixy="0" ixz="0" iyy="1.754e-06" iyz="0" izz="2.45e-06"/>
    </inertial>
  </link>
  <gazebo reference="head">
    <collision>
      <surface>
        <friction>
          <ode>
            <mu>0.4</mu>
            <mu2>0.4</mu2>
          </ode>
          <bullet>
            <friction>0.4</friction>
            <friction2>0.4</friction2>
          </bullet>
        </friction>
        <contact>
          <ode>
            <soft_erp>0.2</soft_erp>
            <soft_cfm>1e-9</soft_cfm>
            <kp>0</kp>
            <kd>1</kd>
            <max_vel>0.01</max_vel>
            <min_depth>0</min_depth>
          </ode>
          <bullet>
            <kp>0</kp>
            <kd>1</kd>
          </bullet>
        </contact>
      </surface>
    </collision>
    <!--<mu1>${config.link.friction1}</mu1>
      <mu2>${config.link.friction2}</mu2>
      <kp>${config.link.kp}</kp>
      <kd>${config.link.kd}</kd>-->
    <self_collide>false</self_collide>
    <material>Gazebo/Grey</material>
  </gazebo>
  <link name="base_link"/>
  <link name="body">
    <visual>
      <origin rpy="0 0 0" xyz="0 0 0"/>
      <geometry>
        <box size="0.05 0.11 0.094"/>
      </geometry>
      <material name="Grey"/>
    </visual>
    <collision>
      <origin rpy="0 0 0" xyz="0 0 0"/>
      <geometry>
        <box size="0.05 0.11 0.094"/>
      </geometry>
    </collision>
    <inertial>
      <origin xyz="0 0 0"/>
      <mass value="0.233"/>
      <inertia ixx="0.000406507333333" ixy="0" ixz="0" iyy="0.000220107333333" iyz="0" izz="0.000283483333333"/>
    </inertial>
  </link>
  <gazebo reference="body">
    <collision>
      <surface>
        <friction>
          <ode>
            <mu>0.4</mu>
            <mu2>0.4</mu2>
          </ode>
          <bullet>
            <friction>0.4</friction>
            <friction2>0.4</friction2>
          </bullet>
        </friction>
        <contact>
          <ode>
            <soft_erp>0.2</soft_erp>
            <soft_cfm>1e-9</soft_cfm>
            <kp>0</kp>
            <kd>1</kd>
            <max_vel>0.01</max_vel>
            <min_depth>0</min_depth>
          </ode>
          <bullet>
            <kp>0</kp>
            <kd>1</kd>
          </bullet>
        </contact>
      </surface>
    </collision>
    <!--<mu1>${config.link.friction1}</mu1>
      <mu2>${config.link.friction2}</mu2>
      <kp>${config.link.kp}</kp>
      <kd>${config.link.kd}</kd>-->
    <self_collide>false</self_collide>
    <material>Gazebo/Grey</material>
    <sensor name="imu_sensor" type="imu">
      <always_on>true</always_on>
      <update_rate>100.0</update_rate>
      <visualize>true</visualize>
      <topic>imu</topic>
      <plugin filename="libgazebo_ros_imu_sensor.so" name="imu_plugin">
        <robotNamespace>/yamax</robotNamespace>
        <topicName>imu</topicName>
        <bodyName>body</bodyName>
        <updateRateHZ>10.0</updateRateHZ>
        <gaussianNoise>0.0</gaussianNoise>
        <xyzOffset>0 0 0</xyzOffset>
        <rpyOffset>0 0 0</rpyOffset>
        <frameName>body</frameName>
      </plugin>
      <pose>0 0 0 0 0 0</pose>
    </sensor>
  </gazebo>
  <link name="arm_right_virtual">
    <inertial>
      <origin xyz="0 0 0"/>
      <mass value="0.00457"/>
      <inertia ixx="0.0" ixy="0" ixz="0" iyy="0.0" iyz="0" izz="0.0"/>
    </inertial>
  </link>
  <link name="arm_right_1">
    <visual>
      <origin rpy="0 0 0" xyz="0 0 -0.045"/>
      <geometry>
        <box size="0.004 0.02 0.09"/>
      </geometry>
      <material name="Orange"/>
    </visual>
    <collision>
      <origin rpy="0 0 0" xyz="0 0 -0.045"/>
      <geometry>
        <box size="0.004 0.02 0.09"/>
      </geometry>
    </collision>
    <inertial>
      <origin xyz="0 0 -0.045"/>
      <mass value="0.00457"/>
      <inertia ixx="3.23708333333e-06" ixy="0" ixz="0" iyy="3.10912333333e-06" iyz="0" izz="1.76706666667e-07"/>
    </inertial>
  </link>
  <gazebo reference="arm_right_1">
    <collision>
      <surface>
        <friction>
          <ode>
            <mu>0.4</mu>
            <mu2>0.4</mu2>
          </ode>
          <bullet>
            <friction>0.4</friction>
            <friction2>0.4</friction2>
          </bullet>
        </friction>
        <contact>
          <ode>
            <soft_erp>0.2</soft_erp>
            <soft_cfm>1e-9</soft_cfm>
            <kp>0</kp>
            <kd>1</kd>
            <max_vel>0.01</max_vel>
            <min_depth>0</min_depth>
          </ode>
          <bullet>
            <kp>0</kp>
            <kd>1</kd>
          </bullet>
        </contact>
      </surface>
    </collision>
    <!--<mu1>${config.link.friction1}</mu1>
      <mu2>${config.link.friction2}</mu2>
      <kp>${config.link.kp}</kp>
      <kd>${config.link.kd}</kd>-->
    <self_collide>false</self_collide>
    <material>Gazebo/Orange</material>
  </gazebo>
  <link name="arm_right_2">
    <visual>
      <origin rpy="0 0 0" xyz="0 0 -0.03"/>
      <geometry>
        <box size="0.004 0.02 0.06"/>
      </geometry>
      <material name="Orange"/>
    </visual>
    <collision>
      <origin rpy="0 0 0" xyz="0 0 -0.03"/>
      <geometry>
        <box size="0.004 0.02 0.06"/>
      </geometry>
    </collision>
    <inertial>
      <origin xyz="0 0 -0.03"/>
      <mass value="0.00355"/>
      <inertia ixx="1.18333333333e-06" ixy="0" ixz="0" iyy="1.08393333333e-06" iyz="0" izz="1.37266666667e-07"/>
    </inertial>
  </link>
  <gazebo reference="arm_right_2">
    <collision>
      <surface>
        <friction>
          <ode>
            <mu>0.4</mu>
            <mu2>0.4</mu2>
          </ode>
          <bullet>
            <friction>0.4</friction>
            <friction2>0.4</friction2>
          </bullet>
        </friction>
        <contact>
          <ode>
            <soft_erp>0.2</soft_erp>
            <soft_cfm>1e-9</soft_cfm>
            <kp>0</kp>
            <kd>1</kd>
            <max_vel>0.01</max_vel>
            <min_depth>0</min_depth>
          </ode>
          <bullet>
            <kp>0</kp>
            <kd>1</kd>
          </bullet>
        </contact>
      </surface>
    </collision>
    <!--<mu1>${config.link.friction1}</mu1>
      <mu2>${config.link.friction2}</mu2>
      <kp>${config.link.kp}</kp>
      <kd>${config.link.kd}</kd>-->
    <self_collide>false</self_collide>
    <material>Gazebo/Orange</material>
  </gazebo>
  <link name="arm_left_virtual">
    <inertial>
      <origin xyz="0 0 0"/>
      <mass value="0.00457"/>
      <inertia ixx="0.0" ixy="0" ixz="0" iyy="0.0" iyz="0" izz="0.0"/>
    </inertial>
  </link>
  <link name="arm_left_1">
    <visual>
      <origin rpy="0 0 0" xyz="0 0 -0.045"/>
      <geometry>
        <box size="0.004 0.02 0.09"/>
      </geometry>
      <material name="Orange"/>
    </visual>
    <collision>
      <origin rpy="0 0 0" xyz="0 0 -0.045"/>
      <geometry>
        <box size="0.004 0.02 0.09"/>
      </geometry>
    </collision>
    <inertial>
      <origin xyz="0 0 -0.045"/>
      <mass value="0.00457"/>
      <inertia ixx="3.23708333333e-06" ixy="0" ixz="0" iyy="3.10912333333e-06" iyz="0" izz="1.76706666667e-07"/>
    </inertial>
  </link>
  <gazebo reference="arm_left_1">
    <collision>
      <surface>
        <friction>
          <ode>
            <mu>0.4</mu>
            <mu2>0.4</mu2>
          </ode>
          <bullet>
            <friction>0.4</friction>
            <friction2>0.4</friction2>
          </bullet>
        </friction>
        <contact>
          <ode>
            <soft_erp>0.2</soft_erp>
            <soft_cfm>1e-9</soft_cfm>
            <kp>0</kp>
            <kd>1</kd>
            <max_vel>0.01</max_vel>
            <min_depth>0</min_depth>
          </ode>
          <bullet>
            <kp>0</kp>
            <kd>1</kd>
          </bullet>
        </contact>
      </surface>
    </collision>
    <!--<mu1>${config.link.friction1}</mu1>
      <mu2>${config.link.friction2}</mu2>
      <kp>${config.link.kp}</kp>
      <kd>${config.link.kd}</kd>-->
    <self_collide>false</self_collide>
    <material>Gazebo/Orange</material>
  </gazebo>
  <link name="arm_left_2">
    <visual>
      <origin rpy="0 0 0" xyz="0 0 -0.03"/>
      <geometry>
        <box size="0.004 0.02 0.06"/>
      </geometry>
      <material name="Orange"/>
    </visual>
    <collision>
      <origin rpy="0 0 0" xyz="0 0 -0.03"/>
      <geometry>
        <box size="0.004 0.02 0.06"/>
      </geometry>
    </collision>
    <inertial>
      <origin xyz="0 0 -0.03"/>
      <mass value="0.00355"/>
      <inertia ixx="1.18333333333e-06" ixy="0" ixz="0" iyy="1.08393333333e-06" iyz="0" izz="1.37266666667e-07"/>
    </inertial>
  </link>
  <gazebo reference="arm_left_2">
    <collision>
      <surface>
        <friction>
          <ode>
            <mu>0.4</mu>
            <mu2>0.4</mu2>
          </ode>
          <bullet>
            <friction>0.4</friction>
            <friction2>0.4</friction2>
          </bullet>
        </friction>
        <contact>
          <ode>
            <soft_erp>0.2</soft_erp>
            <soft_cfm>1e-9</soft_cfm>
            <kp>0</kp>
            <kd>1</kd>
            <max_vel>0.01</max_vel>
            <min_depth>0</min_depth>
          </ode>
          <bullet>
            <kp>0</kp>
            <kd>1</kd>
          </bullet>
        </contact>
      </surface>
    </collision>
    <!--<mu1>${config.link.friction1}</mu1>
      <mu2>${config.link.friction2}</mu2>
      <kp>${config.link.kp}</kp>
      <kd>${config.link.kd}</kd>-->
    <self_collide>false</self_collide>
    <material>Gazebo/Orange</material>
  </gazebo>
  <link name="stomach">
    <visual>
      <origin rpy="0 0 0" xyz="0 0 -0.035"/>
      <geometry>
        <box size="0.054 0.053 0.07"/>
      </geometry>
      <material name="Grey"/>
    </visual>
    <collision>
      <origin rpy="0 0 0" xyz="0 0 -0.035"/>
      <geometry>
        <box size="0.054 0.053 0.07"/>
      </geometry>
    </collision>
    <inertial>
      <origin xyz="0 0 -0.035"/>
      <mass value="0.00972"/>
      <inertia ixx="6.24429e-06" ixy="0" ixz="0" iyy="6.33096e-06" iyz="0" izz="4.63725e-06"/>
    </inertial>
  </link>
  <gazebo reference="stomach">
    <collision>
      <surface>
        <friction>
          <ode>
            <mu>0.4</mu>
            <mu2>0.4</mu2>
          </ode>
          <bullet>
            <friction>0.4</friction>
            <friction2>0.4</friction2>
          </bullet>
        </friction>
        <contact>
          <ode>
            <soft_erp>0.2</soft_erp>
            <soft_cfm>1e-9</soft_cfm>
            <kp>0</kp>
            <kd>1</kd>
            <max_vel>0.01</max_vel>
            <min_depth>0</min_depth>
          </ode>
          <bullet>
            <kp>0</kp>
            <kd>1</kd>
          </bullet>
        </contact>
      </surface>
    </collision>
    <!--<mu1>${config.link.friction1}</mu1>
      <mu2>${config.link.friction2}</mu2>
      <kp>${config.link.kp}</kp>
      <kd>${config.link.kd}</kd>-->
    <self_collide>false</self_collide>
    <material>Gazebo/Grey</material>
  </gazebo>
  <link name="hip">
    <visual>
      <origin rpy="0 0 0" xyz="0 0 -0.0025"/>
      <geometry>
        <box size="0.05 0.11 0.004"/>
      </geometry>
      <material name="Orange"/>
    </visual>
    <collision>
      <origin rpy="0 0 0" xyz="0 0 -0.0025"/>
      <geometry>
        <box size="0.05 0.11 0.004"/>
      </geometry>
    </collision>
    <inertial>
      <origin xyz="0 0 -0.0025"/>
      <mass value="0.072"/>
      <inertia ixx="7.2696e-05" ixy="0" ixz="0" iyy="1.5096e-05" iyz="0" izz="8.76e-05"/>
    </inertial>
  </link>
  <gazebo reference="hip">
    <collision>
      <surface>
        <friction>
          <ode>
            <mu>0.4</mu>
            <mu2>0.4</mu2>
          </ode>
          <bullet>
            <friction>0.4</friction>
            <friction2>0.4</friction2>
          </bullet>
        </friction>
        <contact>
          <ode>
            <soft_erp>0.2</soft_erp>
            <soft_cfm>1e-9</soft_cfm>
            <kp>0</kp>
            <kd>1</kd>
            <max_vel>0.01</max_vel>
            <min_depth>0</min_depth>
          </ode>
          <bullet>
            <kp>0</kp>
            <kd>1</kd>
          </bullet>
        </contact>
      </surface>
    </collision>
    <!--<mu1>${config.link.friction1}</mu1>
      <mu2>${config.link.friction2}</mu2>
      <kp>${config.link.kp}</kp>
      <kd>${config.link.kd}</kd>-->
    <self_collide>false</self_collide>
    <material>Gazebo/Orange</material>
  </gazebo>
  <link name="hip_right">
    <visual>
      <origin rpy="0 0 0" xyz="0 0 -0.0225"/>
      <geometry>
        <box size="0.055 0.045 0.045"/>
      </geometry>
      <material name="Black"/>
    </visual>
    <collision>
      <origin rpy="0 0 0" xyz="0 0 -0.0225"/>
      <geometry>
        <box size="0.055 0.045 0.045"/>
      </geometry>
    </collision>
    <inertial>
      <origin xyz="0 0 -0.0225"/>
      <mass value="0.131"/>
      <inertia ixx="4.42125e-05" ixy="0" ixz="0" iyy="5.51291666667e-05" iyz="0" izz="5.51291666667e-05"/>
    </inertial>
  </link>
  <gazebo reference="hip_right">
    <collision>
      <surface>
        <friction>
          <ode>
            <mu>0.4</mu>
            <mu2>0.4</mu2>
          </ode>
          <bullet>
            <friction>0.4</friction>
            <friction2>0.4</friction2>
          </bullet>
        </friction>
        <contact>
          <ode>
            <soft_erp>0.2</soft_erp>
            <soft_cfm>1e-9</soft_cfm>
            <kp>0</kp>
            <kd>1</kd>
            <max_vel>0.01</max_vel>
            <min_depth>0</min_depth>
          </ode>
          <bullet>
            <kp>0</kp>
            <kd>1</kd>
          </bullet>
        </contact>
      </surface>
    </collision>
    <!--<mu1>${config.link.friction1}</mu1>
      <mu2>${config.link.friction2}</mu2>
      <kp>${config.link.kp}</kp>
      <kd>${config.link.kd}</kd>-->
    <self_collide>false</self_collide>
    <material>Gazebo/Black</material>
  </gazebo>
  <link name="leg_right_1">
    <visual>
      <origin rpy="0 0 0" xyz="0 0 -0.0115"/>
      <geometry>
        <box size="0.045 0.045 0.023"/>
      </geometry>
      <material name="Black"/>
    </visual>
    <collision>
      <origin rpy="0 0 0" xyz="0 0 -0.0115"/>
      <geometry>
        <box size="0.045 0.045 0.023"/>
      </geometry>
    </collision>
    <inertial>
      <origin xyz="0 0 -0.0115"/>
      <mass value="0.0599"/>
      <inertia ixx="1.27487166667e-05" ixy="0" ixz="0" iyy="1.27487166667e-05" iyz="0" izz="2.021625e-05"/>
    </inertial>
  </link>
  <gazebo reference="leg_right_1">
    <collision>
      <surface>
        <friction>
          <ode>
            <mu>0.4</mu>
            <mu2>0.4</mu2>
          </ode>
          <bullet>
            <friction>0.4</friction>
            <friction2>0.4</friction2>
          </bullet>
        </friction>
        <contact>
          <ode>
            <soft_erp>0.2</soft_erp>
            <soft_cfm>1e-9</soft_cfm>
            <kp>0</kp>
            <kd>1</kd>
            <max_vel>0.01</max_vel>
            <min_depth>0</min_depth>
          </ode>
          <bullet>
            <kp>0</kp>
            <kd>1</kd>
          </bullet>
        </contact>
      </surface>
    </collision>
    <!--<mu1>${config.link.friction1}</mu1>
      <mu2>${config.link.friction2}</mu2>
      <kp>${config.link.kp}</kp>
      <kd>${config.link.kd}</kd>-->
    <self_collide>false</self_collide>
    <material>Gazebo/Black</material>
  </gazebo>
  <link name="leg_right_2">
    <visual>
      <origin rpy="0 0 0" xyz="0 0 -0.0175"/>
      <geometry>
        <box size="0.022 0.06 0.035"/>
      </geometry>
      <material name="Orange"/>
    </visual>
    <collision>
      <origin rpy="0 0 0" xyz="0 0 -0.0175"/>
      <geometry>
        <box size="0.022 0.06 0.035"/>
      </geometry>
    </collision>
    <inertial>
      <origin xyz="0 0 -0.0175"/>
      <mass value="0.0036"/>
      <inertia ixx="1.4475e-06" ixy="0" ixz="0" iyy="5.127e-07" iyz="0" izz="1.2252e-06"/>
    </inertial>
  </link>
  <gazebo reference="leg_right_2">
    <collision>
      <surface>
        <friction>
          <ode>
            <mu>0.4</mu>
            <mu2>0.4</mu2>
          </ode>
          <bullet>
            <friction>0.4</friction>
            <friction2>0.4</friction2>
          </bullet>
        </friction>
        <contact>
          <ode>
            <soft_erp>0.2</soft_erp>
            <soft_cfm>1e-9</soft_cfm>
            <kp>0</kp>
            <kd>1</kd>
            <max_vel>0.01</max_vel>
            <min_depth>0</min_depth>
          </ode>
          <bullet>
            <kp>0</kp>
            <kd>1</kd>
          </bullet>
        </contact>
      </surface>
    </collision>
    <!--<mu1>${config.link.friction1}</mu1>
      <mu2>${config.link.friction2}</mu2>
      <kp>${config.link.kp}</kp>
      <kd>${config.link.kd}</kd>-->
    <self_collide>false</self_collide>
    <material>Gazebo/Orange</material>
  </gazebo>
  <link name="leg_right_3">
    <visual>
      <origin rpy="0 0 0" xyz="0 0 -0.021"/>
      <geometry>
        <box size="0.055 0.045 0.042"/>
      </geometry>
      <material name="Black"/>
    </visual>
    <collision>
      <origin rpy="0 0 0" xyz="0 0 -0.021"/>
      <geometry>
        <box size="0.055 0.045 0.042"/>
      </geometry>
    </collision>
    <inertial>
      <origin xyz="0 0 -0.021"/>
      <mass value="0.131"/>
      <inertia ixx="4.136325e-05" ixy="0" ixz="0" iyy="5.22799166667e-05" iyz="0" izz="5.51291666667e-05"/>
    </inertial>
  </link>
  <gazebo reference="leg_right_3">
    <collision>
      <surface>
        <friction>
          <ode>
            <mu>0.4</mu>
            <mu2>0.4</mu2>
          </ode>
          <bullet>
            <friction>0.4</friction>
            <friction2>0.4</friction2>
          </bullet>
        </friction>
        <contact>
          <ode>
            <soft_erp>0.2</soft_erp>
            <soft_cfm>1e-9</soft_cfm>
            <kp>0</kp>
            <kd>1</kd>
            <max_vel>0.01</max_vel>
            <min_depth>0</min_depth>
          </ode>
          <bullet>
            <kp>0</kp>
            <kd>1</kd>
          </bullet>
        </contact>
      </surface>
    </collision>
    <!--<mu1>${config.link.friction1}</mu1>
      <mu2>${config.link.friction2}</mu2>
      <kp>${config.link.kp}</kp>
      <kd>${config.link.kd}</kd>-->
    <self_collide>false</self_collide>
    <material>Gazebo/Black</material>
  </gazebo>
  <link name="hip_left">
    <visual>
      <origin rpy="0 0 0" xyz="0 0 -0.0225"/>
      <geometry>
        <box size="0.055 0.045 0.045"/>
      </geometry>
      <material name="Black"/>
    </visual>
    <collision>
      <origin rpy="0 0 0" xyz="0 0 -0.0225"/>
      <geometry>
        <box size="0.055 0.045 0.045"/>
      </geometry>
    </collision>
    <inertial>
      <origin xyz="0 0 -0.0225"/>
      <mass value="0.131"/>
      <inertia ixx="4.42125e-05" ixy="0" ixz="0" iyy="5.51291666667e-05" iyz="0" izz="5.51291666667e-05"/>
    </inertial>
  </link>
  <gazebo reference="hip_left">
    <collision>
      <surface>
        <friction>
          <ode>
            <mu>0.4</mu>
            <mu2>0.4</mu2>
          </ode>
          <bullet>
            <friction>0.4</friction>
            <friction2>0.4</friction2>
          </bullet>
        </friction>
        <contact>
          <ode>
            <soft_erp>0.2</soft_erp>
            <soft_cfm>1e-9</soft_cfm>
            <kp>0</kp>
            <kd>1</kd>
            <max_vel>0.01</max_vel>
            <min_depth>0</min_depth>
          </ode>
          <bullet>
            <kp>0</kp>
            <kd>1</kd>
          </bullet>
        </contact>
      </surface>
    </collision>
    <!--<mu1>${config.link.friction1}</mu1>
      <mu2>${config.link.friction2}</mu2>
      <kp>${config.link.kp}</kp>
      <kd>${config.link.kd}</kd>-->
    <self_collide>false</self_collide>
    <material>Gazebo/Black</material>
  </gazebo>
  <link name="leg_left_1">
    <visual>
      <origin rpy="0 0 0" xyz="0 0 -0.0115"/>
      <geometry>
        <box size="0.045 0.045 0.023"/>
      </geometry>
      <material name="Black"/>
    </visual>
    <collision>
      <origin rpy="0 0 0" xyz="0 0 -0.0115"/>
      <geometry>
        <box size="0.045 0.045 0.023"/>
      </geometry>
    </collision>
    <inertial>
      <origin xyz="0 0 -0.0115"/>
      <mass value="0.0599"/>
      <inertia ixx="1.27487166667e-05" ixy="0" ixz="0" iyy="1.27487166667e-05" iyz="0" izz="2.021625e-05"/>
    </inertial>
  </link>
  <gazebo reference="leg_left_1">
    <collision>
      <surface>
        <friction>
          <ode>
            <mu>0.4</mu>
            <mu2>0.4</mu2>
          </ode>
          <bullet>
            <friction>0.4</friction>
            <friction2>0.4</friction2>
          </bullet>
        </friction>
        <contact>
          <ode>
            <soft_erp>0.2</soft_erp>
            <soft_cfm>1e-9</soft_cfm>
            <kp>0</kp>
            <kd>1</kd>
            <max_vel>0.01</max_vel>
            <min_depth>0</min_depth>
          </ode>
          <bullet>
            <kp>0</kp>
            <kd>1</kd>
          </bullet>
        </contact>
      </surface>
    </collision>
    <!--<mu1>${config.link.friction1}</mu1>
      <mu2>${config.link.friction2}</mu2>
      <kp>${config.link.kp}</kp>
      <kd>${config.link.kd}</kd>-->
    <self_collide>false</self_collide>
    <material>Gazebo/Black</material>
  </gazebo>
  <link name="leg_left_2">
    <visual>
      <origin rpy="0 0 0" xyz="0 0 -0.0175"/>
      <geometry>
        <box size="0.022 0.06 0.035"/>
      </geometry>
      <material name="Orange"/>
    </visual>
    <collision>
      <origin rpy="0 0 0" xyz="0 0 -0.0175"/>
      <geometry>
        <box size="0.022 0.06 0.035"/>
      </geometry>
    </collision>
    <inertial>
      <origin xyz="0 0 -0.0175"/>
      <mass value="0.0036"/>
      <inertia ixx="1.4475e-06" ixy="0" ixz="0" iyy="5.127e-07" iyz="0" izz="1.2252e-06"/>
    </inertial>
  </link>
  <gazebo reference="leg_left_2">
    <collision>
      <surface>
        <friction>
          <ode>
            <mu>0.4</mu>
            <mu2>0.4</mu2>
          </ode>
          <bullet>
            <friction>0.4</friction>
            <friction2>0.4</friction2>
          </bullet>
        </friction>
        <contact>
          <ode>
            <soft_erp>0.2</soft_erp>
            <soft_cfm>1e-9</soft_cfm>
            <kp>0</kp>
            <kd>1</kd>
            <max_vel>0.01</max_vel>
            <min_depth>0</min_depth>
          </ode>
          <bullet>
            <kp>0</kp>
            <kd>1</kd>
          </bullet>
        </contact>
      </surface>
    </collision>
    <!--<mu1>${config.link.friction1}</mu1>
      <mu2>${config.link.friction2}</mu2>
      <kp>${config.link.kp}</kp>
      <kd>${config.link.kd}</kd>-->
    <self_collide>false</self_collide>
    <material>Gazebo/Orange</material>
  </gazebo>
  <link name="leg_left_3">
    <visual>
      <origin rpy="0 0 0" xyz="0 0 -0.021"/>
      <geometry>
        <box size="0.055 0.045 0.042"/>
      </geometry>
      <material name="Black"/>
    </visual>
    <collision>
      <origin rpy="0 0 0" xyz="0 0 -0.021"/>
      <geometry>
        <box size="0.055 0.045 0.042"/>
      </geometry>
    </collision>
    <inertial>
      <origin xyz="0 0 -0.021"/>
      <mass value="0.131"/>
      <inertia ixx="4.136325e-05" ixy="0" ixz="0" iyy="5.22799166667e-05" iyz="0" izz="5.51291666667e-05"/>
    </inertial>
  </link>
  <gazebo reference="leg_left_3">
    <collision>
      <surface>
        <friction>
          <ode>
            <mu>0.4</mu>
            <mu2>0.4</mu2>
          </ode>
          <bullet>
            <friction>0.4</friction>
            <friction2>0.4</friction2>
          </bullet>
        </friction>
        <contact>
          <ode>
            <soft_erp>0.2</soft_erp>
            <soft_cfm>1e-9</soft_cfm>
            <kp>0</kp>
            <kd>1</kd>
            <max_vel>0.01</max_vel>
            <min_depth>0</min_depth>
          </ode>
          <bullet>
            <kp>0</kp>
            <kd>1</kd>
          </bullet>
        </contact>
      </surface>
    </collision>
    <!--<mu1>${config.link.friction1}</mu1>
      <mu2>${config.link.friction2}</mu2>
      <kp>${config.link.kp}</kp>
      <kd>${config.link.kd}</kd>-->
    <self_collide>false</self_collide>
    <material>Gazebo/Black</material>
  </gazebo>
  <link name="foot_right">
    <visual>
      <origin rpy="0 0 0" xyz="0 0 -0.002"/>
      <geometry>
        <box size="0.09 0.06 0.004"/>
      </geometry>
      <material name="Orange"/>
    </visual>
    <collision>
      <origin rpy="0 0 0" xyz="0 0 -0.002"/>
      <geometry>
        <box size="0.09 0.06 0.004"/>
      </geometry>
    </collision>
    <inertial>
      <origin xyz="0 0 -0.002"/>
      <mass value="0.0209"/>
      <inertia ixx="6.29786666667e-06" ixy="0" ixz="0" iyy="1.41353666667e-05" iyz="0" izz="2.03775e-05"/>
    </inertial>
  </link>
  <gazebo reference="foot_right">
    <collision>
      <surface>
        <friction>
          <ode>
            <mu>0.4</mu>
            <mu2>0.4</mu2>
          </ode>
          <bullet>
            <friction>0.4</friction>
            <friction2>0.4</friction2>
          </bullet>
        </friction>
        <contact>
          <ode>
            <soft_erp>0.2</soft_erp>
            <soft_cfm>1e-9</soft_cfm>
            <kp>0</kp>
            <kd>1</kd>
            <max_vel>0.01</max_vel>
            <min_depth>0</min_depth>
          </ode>
          <bullet>
            <kp>0</kp>
            <kd>1</kd>
          </bullet>
        </contact>
      </surface>
    </collision>
    <!--<mu1>${config.link.friction1}</mu1>
      <mu2>${config.link.friction2}</mu2>
      <kp>${config.link.kp}</kp>
      <kd>${config.link.kd}</kd>-->
    <self_collide>false</self_collide>
    <material>Gazebo/Orange</material>
  </gazebo>
  <link name="foot_left">
    <visual>
      <origin rpy="0 0 0" xyz="0 0 -0.002"/>
      <geometry>
        <box size="0.09 0.06 0.004"/>
      </geometry>
      <material name="Orange"/>
    </visual>
    <collision>
      <origin rpy="0 0 0" xyz="0 0 -0.002"/>
      <geometry>
        <box size="0.09 0.06 0.004"/>
      </geometry>
    </collision>
    <inertial>
      <origin xyz="0 0 -0.002"/>
      <mass value="0.0209"/>
      <inertia ixx="6.29786666667e-06" ixy="0" ixz="0" iyy="1.41353666667e-05" iyz="0" izz="2.03775e-05"/>
    </inertial>
  </link>
  <gazebo reference="foot_left">
    <collision>
      <surface>
        <friction>
          <ode>
            <mu>0.4</mu>
            <mu2>0.4</mu2>
          </ode>
          <bullet>
            <friction>0.4</friction>
            <friction2>0.4</friction2>
          </bullet>
        </friction>
        <contact>
          <ode>
            <soft_erp>0.2</soft_erp>
            <soft_cfm>1e-9</soft_cfm>
            <kp>0</kp>
            <kd>1</kd>
            <max_vel>0.01</max_vel>
            <min_depth>0</min_depth>
          </ode>
          <bullet>
            <kp>0</kp>
            <kd>1</kd>
          </bullet>
        </contact>
      </surface>
    </collision>
    <!--<mu1>${config.link.friction1}</mu1>
      <mu2>${config.link.friction2}</mu2>
      <kp>${config.link.kp}</kp>
      <kd>${config.link.kd}</kd>-->
    <self_collide>false</self_collide>
    <material>Gazebo/Orange</material>
  </gazebo>
  <joint name="neck" type="revolute">
    <parent link="body"/>
    <child link="head"/>
    <origin rpy="0 0 0" xyz="-0.004 0 0.07"/>
    <axis xyz="0 0 1"/>
    <limit effort="1" lower="-1.5708" upper="1.5708" velocity="0.001"/>
  </joint>
  <transmission name="neck_transmission">
    <type>transmission_interface/SimpleTransmission</type>
    <joint name="neck">
      <hardwareInterface>hardware_interface/PositionJointInterface</hardwareInterface>
    </joint>
    <actuator name="A">
      <mechanicalReduction>1.0</mechanicalReduction>
    </actuator>
  </transmission>
  <joint name="dummy_joint" type="fixed">
    <parent link="base_link"/>
    <child link="body"/>
  </joint>
  <joint name="shoulder_right_x" type="revolute">
    <parent link="body"/>
    <child link="arm_right_virtual"/>
    <origin rpy="0 0 0" xyz="0.025 -0.075 0.04"/>
    <axis xyz="0 1 0"/>
    <limit effort="1" lower="-1.5708" upper="1.5708" velocity="0.001"/>
  </joint>
  <transmission name="shoulder_right_x_transmission">
    <type>transmission_interface/SimpleTransmission</type>
    <joint name="shoulder_right_x">
      <hardwareInterface>hardware_interface/PositionJointInterface</hardwareInterface>
    </joint>
    <actuator name="E">
      <mechanicalReduction>1.0</mechanicalReduction>
    </actuator>
  </transmission>
  <joint name="shoulder_right_z" type="revolute">
    <parent link="arm_right_virtual"/>
    <child link="arm_right_1"/>
    <origin rpy="0 0 0" xyz="0 0 0"/>
    <axis xyz="1 0 0"/>
    <limit effort="1" lower="-1.5708" upper="1.5708" velocity="0.001"/>
  </joint>
  <transmission name="shoulder_right_z_transmission">
    <type>transmission_interface/SimpleTransmission</type>
    <joint name="shoulder_right_z">
      <hardwareInterface>hardware_interface/PositionJointInterface</hardwareInterface>
    </joint>
    <actuator name="F">
      <mechanicalReduction>1.0</mechanicalReduction>
    </actuator>
  </transmission>
  <joint name="shoulder_left_x" type="revolute">
    <parent link="body"/>
    <child link="arm_left_virtual"/>
    <origin rpy="0 0 0" xyz="0.025 0.075 0.04"/>
    <axis xyz="0 1 0"/>
    <limit effort="1" lower="-1.5708" upper="1.5708" velocity="0.001"/>
  </joint>
  <transmission name="shoulder_left_x_transmission">
    <type>transmission_interface/SimpleTransmission</type>
    <joint name="shoulder_left_x">
      <hardwareInterface>hardware_interface/PositionJointInterface</hardwareInterface>
    </joint>
    <actuator name="B">
      <mechanicalReduction>1.0</mechanicalReduction>
    </actuator>
  </transmission>
  <joint name="shoulder_left_z" type="revolute">
    <parent link="arm_left_virtual"/>
    <child link="arm_left_1"/>
    <origin rpy="0 0 0" xyz="0 0 0"/>
    <axis xyz="1 0 0"/>
    <limit effort="1" lower="-1.5708" upper="1.5708" velocity="0.001"/>
  </joint>
  <transmission name="shoulder_left_z_transmission">
    <type>transmission_interface/SimpleTransmission</type>
    <joint name="shoulder_left_z">
      <hardwareInterface>hardware_interface/PositionJointInterface</hardwareInterface>
    </joint>
    <actuator name="C">
      <mechanicalReduction>1.0</mechanicalReduction>
    </actuator>
  </transmission>
  <joint name="elbow_right" type="revolute">
    <parent link="arm_right_1"/>
    <child link="arm_right_2"/>
    <origin rpy="0 0 -1.5708" xyz="-0.01 -0.02 -0.08"/>
    <axis xyz="1 0 0"/>
    <limit effort="1" lower="-1.5708" upper="1.5708" velocity="0.001"/>
  </joint>
  <transmission name="elbow_right_transmission">
    <type>transmission_interface/SimpleTransmission</type>
    <joint name="elbow_right">
      <hardwareInterface>hardware_interface/PositionJointInterface</hardwareInterface>
    </joint>
    <actuator name="G">
      <mechanicalReduction>1.0</mechanicalReduction>
    </actuator>
  </transmission>
  <joint name="elbow_left" type="revolute">
    <parent link="arm_left_1"/>
    <child link="arm_left_2"/>
    <origin rpy="0 0 -1.5708" xyz="-0.01 0.02 -0.08"/>
    <axis xyz="1 0 0"/>
    <limit effort="1" lower="-1.5708" upper="1.5708" velocity="0.001"/>
  </joint>
  <transmission name="elbow_left_transmission">
    <type>transmission_interface/SimpleTransmission</type>
    <joint name="elbow_left">
      <hardwareInterface>hardware_interface/PositionJointInterface</hardwareInterface>
    </joint>
    <actuator name="D">
      <mechanicalReduction>1.0</mechanicalReduction>
    </actuator>
  </transmission>
  <joint name="backbone_1" type="revolute">
    <parent link="body"/>
    <child link="stomach"/>
    <origin rpy="0 0 0" xyz="0.004 0 -0.02"/>
    <axis xyz="1 0 0"/>
    <limit effort="1" lower="-1.5708" upper="1.5708" velocity="0.001"/>
  </joint>
  <transmission name="backbone_1_transmission">
    <type>transmission_interface/SimpleTransmission</type>
    <joint name="backbone_1">
      <hardwareInterface>hardware_interface/PositionJointInterface</hardwareInterface>
    </joint>
    <actuator name="H">
      <mechanicalReduction>1.0</mechanicalReduction>
    </actuator>
  </transmission>
  <joint name="backbone_2" type="revolute">
    <parent link="stomach"/>
    <child link="hip"/>
    <origin rpy="0 0 0" xyz="0 0 -0.065"/>
    <axis xyz="0 1 0"/>
    <limit effort="1" lower="-1.5708" upper="1.5708" velocity="0.001"/>
  </joint>
  <transmission name="backbone_2_transmission">
    <type>transmission_interface/SimpleTransmission</type>
    <joint name="backbone_2">
      <hardwareInterface>hardware_interface/PositionJointInterface</hardwareInterface>
    </joint>
    <actuator name="I">
      <mechanicalReduction>1.0</mechanicalReduction>
    </actuator>
  </transmission>
  <joint name="hip_joint_right_z" type="revolute">
    <parent link="hip"/>
    <child link="hip_right"/>
    <origin rpy="0 0 0" xyz="0 -0.035 -0.017"/>
    <axis xyz="1 0 0"/>
    <limit effort="1" lower="-1.5708" upper="1.5708" velocity="0.001"/>
  </joint>
  <transmission name="hip_joint_right_z_transmission">
    <type>transmission_interface/SimpleTransmission</type>
    <joint name="hip_joint_right_z">
      <hardwareInterface>hardware_interface/PositionJointInterface</hardwareInterface>
    </joint>
    <actuator name="K">
      <mechanicalReduction>1.0</mechanicalReduction>
    </actuator>
  </transmission>
  <joint name="hip_joint_right_x" type="revolute">
    <parent link="hip_right"/>
    <child link="leg_right_1"/>
    <origin rpy="0 0 0" xyz="0.01 0 -0.05"/>
    <axis xyz="0 1 0"/>
    <limit effort="1" lower="-1.5708" upper="1.5708" velocity="0.001"/>
  </joint>
  <transmission name="hip_joint_right_x_transmission">
    <type>transmission_interface/SimpleTransmission</type>
    <joint name="hip_joint_right_x">
      <hardwareInterface>hardware_interface/PositionJointInterface</hardwareInterface>
    </joint>
    <actuator name="L">
      <mechanicalReduction>1.0</mechanicalReduction>
    </actuator>
  </transmission>
  <joint name="hip_joint_left_z" type="revolute">
    <parent link="hip"/>
    <child link="hip_left"/>
    <origin rpy="0 0 0" xyz="0 0.035 -0.017"/>
    <axis xyz="1 0 0"/>
    <limit effort="1" lower="-1.5708" upper="1.5708" velocity="0.001"/>
  </joint>
  <transmission name="hip_joint_left_z_transmission">
    <type>transmission_interface/SimpleTransmission</type>
    <joint name="hip_joint_left_z">
      <hardwareInterface>hardware_interface/PositionJointInterface</hardwareInterface>
    </joint>
    <actuator name="Q">
      <mechanicalReduction>1.0</mechanicalReduction>
    </actuator>
  </transmission>
  <joint name="hip_joint_left_x" type="revolute">
    <parent link="hip_left"/>
    <child link="leg_left_1"/>
    <origin rpy="0 0 0" xyz="0.01 0 -0.05"/>
    <axis xyz="0 1 0"/>
    <limit effort="1" lower="-1.5708" upper="1.5708" velocity="0.001"/>
  </joint>
  <transmission name="hip_joint_left_x_transmission">
    <type>transmission_interface/SimpleTransmission</type>
    <joint name="hip_joint_left_x">
      <hardwareInterface>hardware_interface/PositionJointInterface</hardwareInterface>
    </joint>
    <actuator name="R">
      <mechanicalReduction>1.0</mechanicalReduction>
    </actuator>
  </transmission>
  <joint name="knee_right" type="revolute">
    <parent link="leg_right_1"/>
    <child link="leg_right_2"/>
    <origin rpy="0 0 0" xyz="-0.01 0 -0.01"/>
    <axis xyz="0 1 0"/>
    <limit effort="1" lower="-1.5708" upper="1.5708" velocity="0.001"/>
  </joint>
  <transmission name="knee_right_transmission">
    <type>transmission_interface/SimpleTransmission</type>
    <joint name="knee_right">
      <hardwareInterface>hardware_interface/PositionJointInterface</hardwareInterface>
    </joint>
    <actuator name="M">
      <mechanicalReduction>1.0</mechanicalReduction>
    </actuator>
  </transmission>
  <joint name="knee_left" type="revolute">
    <parent link="leg_left_1"/>
    <child link="leg_left_2"/>
    <origin rpy="0 0 0" xyz="-0.01 0 -0.01"/>
    <axis xyz="0 1 0"/>
    <limit effort="1" lower="-1.5708" upper="1.5708" velocity="0.001"/>
  </joint>
  <transmission name="knee_left_transmission">
    <type>transmission_interface/SimpleTransmission</type>
    <joint name="knee_left">
      <hardwareInterface>hardware_interface/PositionJointInterface</hardwareInterface>
    </joint>
    <actuator name="S">
      <mechanicalReduction>1.0</mechanicalReduction>
    </actuator>
  </transmission>
  <joint name="ankle_1_right" type="revolute">
    <parent link="leg_right_2"/>
    <child link="leg_right_3"/>
    <origin rpy="0 0 0" xyz="0 0 -0.02"/>
    <axis xyz="0 1 0"/>
    <limit effort="1" lower="-1.5708" upper="1.5708" velocity="0.001"/>
  </joint>
  <transmission name="ankle_1_right_transmission">
    <type>transmission_interface/SimpleTransmission</type>
    <joint name="ankle_1_right">
      <hardwareInterface>hardware_interface/PositionJointInterface</hardwareInterface>
    </joint>
    <actuator name="N">
      <mechanicalReduction>1.0</mechanicalReduction>
    </actuator>
  </transmission>
  <joint name="ankle_1_left" type="revolute">
    <parent link="leg_left_2"/>
    <child link="leg_left_3"/>
    <origin rpy="0 0 0" xyz="0 0 -0.02"/>
    <axis xyz="0 1 0"/>
    <limit effort="1" lower="-1.5708" upper="1.5708" velocity="0.001"/>
  </joint>
  <transmission name="ankle_1_left_transmission">
    <type>transmission_interface/SimpleTransmission</type>
    <joint name="ankle_1_left">
      <hardwareInterface>hardware_interface/PositionJointInterface</hardwareInterface>
    </joint>
    <actuator name="T">
      <mechanicalReduction>1.0</mechanicalReduction>
    </actuator>
  </transmission>
  <joint name="ankle_2_right" type="revolute">
    <parent link="leg_right_3"/>
    <child link="foot_right"/>
    <origin rpy="0 0 0" xyz="0.01 0 -0.055"/>
    <axis xyz="1 0 0"/>
    <limit effort="1" lower="-1.5708" upper="1.5708" velocity="0.001"/>
  </joint>
  <transmission name="ankle_2_right_transmission">
    <type>transmission_interface/SimpleTransmission</type>
    <joint name="ankle_2_right">
      <hardwareInterface>hardware_interface/PositionJointInterface</hardwareInterface>
    </joint>
    <actuator name="O">
      <mechanicalReduction>1.0</mechanicalReduction>
    </actuator>
  </transmission>
  <joint name="ankle_2_left" type="revolute">
    <parent link="leg_left_3"/>
    <child link="foot_left"/>
    <origin rpy="0 0 0" xyz="0.01 0 -0.055"/>
    <axis xyz="1 0 0"/>
    <limit effort="1" lower="-1.5708" upper="1.5708" velocity="0.001"/>
  </joint>
  <transmission name="ankle_2_left_transmission">
    <type>transmission_interface/SimpleTransmission</type>
    <joint name="ankle_2_left">
      <hardwareInterface>hardware_interface/PositionJointInterface</hardwareInterface>
    </joint>
    <actuator name="U">
      <mechanicalReduction>1.0</mechanicalReduction>
    </actuator>
  </transmission>
  <gazebo>
    <plugin filename="libgazebo_ros_p3d.so" name="ground_truth">
      <robotNamespace>/yamax</robotNamespace>
      <frameName>map</frameName>
      <bodyName>body</bodyName>
      <topicName>odom</topicName>
      <updateRate>30.0</updateRate>
    </plugin>
    <plugin filename="libgazebo_ros_control.so" name="gazebo_ros_control">
      <robotNamespace>/yamax</robotNamespace>
      <robotSimType>gazebo_ros_control/DefaultRobotHWSim</robotSimType>
    </plugin>
  </gazebo>
</robot>

